Workbook
Name AnnualCashFlowToDate: #REF!-#REF!-#REF!-#REF!
Name budget: 'Budget Dashboard'!$L1
Name budget_range: 'Budget Dashboard'!$Q1
Name budget_rank: 'Budget Dashboard'!$R1
Name cc_budget: Calculations!$K1
Name cc_delta: Calculations!$L1
Name cc_in_focus: Calculations!$G1
Name cc_month_number: Calculations!$F1
Name cc_show_remaining_budget: Calculations!$I1
Name cc_show_type: Calculations!$H1
Name cc_tracked: Calculations!$J1
Name cc_type: Calculations!$E1
Name ColumnTitleRegion1..B6.1: #REF!
Name ColumnTitleRegion1..E8.4: #REF!
Name ColumnTitleRegion2..D6.1: #REF!
Name ColumnTitleRegion3..F6.1: #REF!
Name com_rank: 'Budget Dashboard'!$S1
Name comb_rank_norm: 'Budget Dashboard'!$U1
Name comb_rank_norm_run_range: 'Budget Dashboard'!$V1
Name comb_rank_range: 'Budget Dashboard'!$T1
Name comb_rank_unique: 'Budget Dashboard'!$W1
Name current_date: TODAY()
Name DailyCashFlow: SUM(#REF!)
Name expenses_header_row: ROW(Expenses[[#Headers],[Expenses]])
Name expenses_max_row: MAX(ROW(Expenses[]))
Name expenses_min_row: MIN(ROW(Expenses[]))
Name expenses_total_row: ROW('Budget Planning'!$C$33)
Name FirstMonth: UPPER(TEXT(StartDate,"mmm "))
Name header_row_id: 'Budget Dashboard'!$D1
Name income_header_row: ROW(Income[[#Headers],[Income]])
Name income_max_row: MAX(ROW(Income[]))
Name income_min_row: MIN(ROW(Income[]))
Name income_total_row: ROW('Budget Planning'!$C$20)
Name is_cat: 'Budget Dashboard'!$F1
Name is_empty: 'Budget Dashboard'!$H1
Name is_header: 'Budget Dashboard'!$E1
Name is_total: 'Budget Dashboard'!$G1
Name item: 'Budget Dashboard'!$J1
Name MonthlyCashFlowToDate: #REF!
Name NextMonth: UPPER(TEXT(EOMONTH(VALUE(#REF! & "1"),0)+1,"mmm "))
Name out_budget: 'Budget Dashboard'!$AA1
Name out_percent_completed: 'Budget Dashboard'!$AB1
Name out_tracked: 'Budget Dashboard'!$Z1
Name Periods: #REF!
Name row_id: 'Budget Dashboard'!$C1
Name RowTitleRegion1..D2.2: #REF!
Name RowTitleRegion1..D2.3: #REF!
Name RowTitleRegion1..D2.4: #REF!
Name RowTitleRegion1..D2.5: #REF!
Name RowTitleRegion1..D2.6: #REF!
Name RowTitleRegion1..D2.7: #REF!
Name RowTitleRegion1..D2.8: #REF!
Name RowTitleRegion2..C4.2: #REF!
Name RowTitleRegion3..G4.2: #REF!
Name RowTitleRegion4..K4.2: #REF!
Name RowTitleRegion5..O4.2: #REF!
Name RowTitleRegion6..C6.2: #REF!
Name RowTitleRegion7..G6.2: #REF!
Name RowTitleRegion8..K6.2: #REF!
Name RowTitleRegion9..O6.2: #REF!

Sheet Guide 
A1: GUIDE
C6: Budget Start Date
C7: This is a guide for Ahmod: The Settings worksheet should be handled careful, it will be hidden tho, so you'll have to unhide it to set the terms to suite your need.
C12: The budget tracking will be active on the 25th of each month, so if you receive your disposable income earlier you'd have to input the day you want it to start reading yourself. This can be done in the Settings Worksheet
C18: Expense Categories
C19: S/N | D19: Category | E19: Examples
C20: 1 | D20: Edu. & Work Tools | E20: Tuition fees, books, work related tools, certifications, gadgets
C21: 2 | D21: Health & Wellnes | E21: skin & health care, etc
C22: 3 | D22: Transport | E22: Bus tram tickets, taxi/uber, rentals
C23: 4 | D23: House media | E23: elect, water, internet

Sheet Budget Planning
A1: Budget Planning
E3: This is a zero based budget planning: meaning you have to allocate your disposable income to either income, expenses or savings after receiving your income.
C5: Define starting year in Settings ➔ | E5: =starting_year -> 2025 | S5: =E5+1 -> 2026 | AG5: =S5+1 -> 2027 | AU5: =AG5+1 -> 2028 | BI5: =AU5+1 -> 2029 | BW5: =BI5+1 -> 2030 | CK5: =BW5+1 -> 2031 | CY5: =CK5+1 -> 2032
E6: =IF(E7=0,"Jan ✔","Jan") -> Jan ✔ | F6: =IF(F7=0,"Feb ✔","Feb") -> Feb ✔ | G6: =IF(G7=0,"Mar ✔","Mar") -> Mar ✔ | H6: =IF(H7=0,"Apr ✔","Apr") -> Apr ✔ | I6: =IF(I7=0,"May ✔","May") -> May ✔ | J6: =IF(J7=0,"Jun ✔","Jun") -> Jun ✔ | K6: =IF(K7=0,"Jul ✔","Jul") -> Jul ✔ | L6: =IF(L7=0,"Aug ✔","Aug") -> Aug ✔ | M6: =IF(M7=0,"Sep ✔","Sep") -> Sep ✔ | N6: =IF(N7=0,"Oct ✔","Oct") -> Oct ✔ | O6: =IF(O7=0,"Nov ✔","Nov") -> Nov ✔ | P6: =IF(P7=0,"Dec ✔","Dec") -> Dec ✔ | Q6: =IF(Q7=0,"Total ✔","Total") -> Total ✔ | S6: =IF(S7=0,"Jan ✔","Jan") -> Jan ✔ | T6: =IF(T7=0,"Feb ✔","Feb") -> Feb ✔ | U6: =IF(U7=0,"Mar ✔","Mar") -> Mar ✔ | V6: =IF(V7=0,"Apr ✔","Apr") -> Apr ✔ | W6: =IF(W7=0,"May ✔","May") -> May ✔ | X6: =IF(X7=0,"Jun ✔","Jun") -> Jun ✔ | Y6: =IF(Y7=0,"Jul ✔","Jul") -> Jul ✔ | Z6: =IF(Z7=0,"Aug ✔","Aug") -> Aug ✔ | AA6: =IF(AA7=0,"Sep ✔","Sep") -> Sep ✔ | AB6: =IF(AB7=0,"Oct ✔","Oct") -> Oct ✔ | AC6: =IF(AC7=0,"Nov ✔","Nov") -> Nov ✔ | AD6: =IF(AD7=0,"Dec ✔","Dec") -> Dec ✔ | AE6: =IF(AE7=0,"Total ✔","Total") -> Total ✔ | AG6: =IF(AG7=0,"Jan ✔","Jan") -> Jan ✔ | AH6: =IF(AH7=0,"Feb ✔","Feb") -> Feb ✔ | AI6: =IF(AI7=0,"Mar ✔","Mar") -> Mar ✔ | AJ6: =IF(AJ7=0,"Apr ✔","Apr") -> Apr ✔ | AK6: =IF(AK7=0,"May ✔","May") -> May ✔ | AL6: =IF(AL7=0,"Jun ✔","Jun") -> Jun ✔ | AM6: =IF(AM7=0,"Jul ✔","Jul") -> Jul ✔ | AN6: =IF(AN7=0,"Aug ✔","Aug") -> Aug ✔ | AO6: =IF(AO7=0,"Sep ✔","Sep") -> Sep ✔ | AP6: =IF(AP7=0,"Oct ✔","Oct") -> Oct ✔ | AQ6: =IF(AQ7=0,"Nov ✔","Nov") -> Nov ✔ | AR6: =IF(AR7=0,"Dec ✔","Dec") -> Dec ✔ | AS6: =IF(AS7=0,"Total ✔","Total") -> Total ✔ | AU6: =IF(AU7=0,"Jan ✔","Jan") -> Jan ✔ | AV6: =IF(AV7=0,"Feb ✔","Feb") -> Feb ✔ | AW6: =IF(AW7=0,"Mar ✔","Mar") -> Mar ✔ | AX6: =IF(AX7=0,"Apr ✔","Apr") -> Apr ✔ | AY6: =IF(AY7=0,"May ✔","May") -> May ✔ | AZ6: =IF(AZ7=0,"Jun ✔","Jun") -> Jun ✔ | BA6: =IF(BA7=0,"Jul ✔","Jul") -> Jul ✔ | BB6: =IF(BB7=0,"Aug ✔","Aug") -> Aug ✔ | BC6: =IF(BC7=0,"Sep ✔","Sep") -> Sep ✔ | BD6: =IF(BD7=0,"Oct ✔","Oct") -> Oct ✔ | BE6: =IF(BE7=0,"Nov ✔","Nov") -> Nov ✔ | BF6: =IF(BF7=0,"Dec ✔","Dec") -> Dec ✔ | BG6: =IF(BG7=0,"Total ✔","Total") -> Total ✔ | BI6: =IF(BI7=0,"Jan ✔","Jan") -> Jan ✔ | BJ6: =IF(BJ7=0,"Feb ✔","Feb") -> Feb ✔ | BK6: =IF(BK7=0,"Mar ✔","Mar") -> Mar ✔ | BL6: =IF(BL7=0,"Apr ✔","Apr") -> Apr ✔ | BM6: =IF(BM7=0,"May ✔","May") -> May ✔ | BN6: =IF(BN7=0,"Jun ✔","Jun") -> Jun ✔ | BO6: =IF(BO7=0,"Jul ✔","Jul") -> Jul ✔ | BP6: =IF(BP7=0,"Aug ✔","Aug") -> Aug ✔ | BQ6: =IF(BQ7=0,"Sep ✔","Sep") -> Sep ✔ | BR6: =IF(BR7=0,"Oct ✔","Oct") -> Oct ✔ | BS6: =IF(BS7=0,"Nov ✔","Nov") -> Nov ✔ | BT6: =IF(BT7=0,"Dec ✔","Dec") -> Dec ✔ | BU6: =IF(BU7=0,"Total ✔","Total") -> Total ✔ | BW6: =IF(BW7=0,"Jan ✔","Jan") -> Jan ✔ | BX6: =IF(BX7=0,"Feb ✔","Feb") -> Feb ✔ | BY6: =IF(BY7=0,"Mar ✔","Mar") -> Mar ✔ | BZ6: =IF(BZ7=0,"Apr ✔","Apr") -> Apr ✔ | CA6: =IF(CA7=0,"May ✔","May") -> May ✔ | CB6: =IF(CB7=0,"Jun ✔","Jun") -> Jun ✔ | CC6: =IF(CC7=0,"Jul ✔","Jul") -> Jul ✔ | CD6: =IF(CD7=0,"Aug ✔","Aug") -> Aug ✔ | CE6: =IF(CE7=0,"Sep ✔","Sep") -> Sep ✔ | CF6: =IF(CF7=0,"Oct ✔","Oct") -> Oct ✔ | CG6: =IF(CG7=0,"Nov ✔","Nov") -> Nov ✔ | CH6: =IF(CH7=0,"Dec ✔","Dec") -> Dec ✔ | CI6: =IF(CI7=0,"Total ✔","Total") -> Total ✔ | CK6: =IF(CK7=0,"Jan ✔","Jan") -> Jan ✔ | CL6: =IF(CL7=0,"Feb ✔","Feb") -> Feb ✔ | CM6: =IF(CM7=0,"Mar ✔","Mar") -> Mar ✔ | CN6: =IF(CN7=0,"Apr ✔","Apr") -> Apr ✔ | CO6: =IF(CO7=0,"May ✔","May") -> May ✔ | CP6: =IF(CP7=0,"Jun ✔","Jun") -> Jun ✔ | CQ6: =IF(CQ7=0,"Jul ✔","Jul") -> Jul ✔ | CR6: =IF(CR7=0,"Aug ✔","Aug") -> Aug ✔ | CS6: =IF(CS7=0,"Sep ✔","Sep") -> Sep ✔ | CT6: =IF(CT7=0,"Oct ✔","Oct") -> Oct ✔ | CU6: =IF(CU7=0,"Nov ✔","Nov") -> Nov ✔ | CV6: =IF(CV7=0,"Dec ✔","Dec") -> Dec ✔ | CW6: =IF(CW7=0,"Total ✔","Total") -> Total ✔ | CY6: =IF(CY7=0,"Jan ✔","Jan") -> Jan ✔ | CZ6: =IF(CZ7=0,"Feb ✔","Feb") -> Feb ✔ | DA6: =IF(DA7=0,"Mar ✔","Mar") -> Mar ✔ | DB6: =IF(DB7=0,"Apr ✔","Apr") -> Apr ✔ | DC6: =IF(DC7=0,"May ✔","May") -> May ✔ | DD6: =IF(DD7=0,"Jun ✔","Jun") -> Jun ✔ | DE6: =IF(DE7=0,"Jul ✔","Jul") -> Jul ✔ | DF6: =IF(DF7=0,"Aug ✔","Aug") -> Aug ✔ | DG6: =IF(DG7=0,"Sep ✔","Sep") -> Sep ✔ | DH6: =IF(DH7=0,"Oct ✔","Oct") -> Oct ✔ | DI6: =IF(DI7=0,"Nov ✔","Nov") -> Nov ✔ | DJ6: =IF(DJ7=0,"Dec ✔","Dec") -> Dec ✔ | DK6: =IF(DK7=0,"Total ✔","Total") -> Total ✔
C7: To be allocated: | E7: =E20-(E33+E46) -> 0 | F7: =F20-(F33+F46) -> 0 | G7: =G20-(G33+G46) -> 0 | H7: =H20-(H33+H46) -> 0 | I7: =I20-(I33+I46) -> 0 | J7: =J20-(J33+J46) -> 0 | K7: =K20-(K33+K46) -> 0 | L7: =L20-(L33+L46) -> 0 | ... Q7: =Q20-(Q33+Q46) -> 0 | T7: =T20-(T33+T46) -> 0 | U7: =U20-(U33+U46) -> 0 | V7: =V20-(V33+V46) -> 0 | W7: =W20-(W33+W46) -> 0 | X7: =X20-(X33+X46) -> 0 | Y7: =Y20-(Y33+Y46) -> 0 | Z7: =Z20-(Z33+Z46) -> 0 | AA7: =AA20-(AA33+AA46) -> 0 | ... AE7: =AE20-(AE33+AE46) -> 0 | AH7: =AH20-(AH33+AH46) -> 0 | AI7: =AI20-(AI33+AI46) -> 0 | AJ7: =AJ20-(AJ33+AJ46) -> 0 | AK7: =AK20-(AK33+AK46) -> 0 | AL7: =AL20-(AL33+AL46) -> 0 | AM7: =AM20-(AM33+AM46) -> 0 | AN7: =AN20-(AN33+AN46) -> 0 | AO7: =AO20-(AO33+AO46) -> 0 | ... AS7: =AS20-(AS33+AS46) -> 0 | AV7: =AV20-(AV33+AV46) -> 0 | AW7: =AW20-(AW33+AW46) -> 0 | AX7: =AX20-(AX33+AX46) -> 0 | AY7: =AY20-(AY33+AY46) -> 0 | AZ7: =AZ20-(AZ33+AZ46) -> 0 | BA7: =BA20-(BA33+BA46) -> 0 | BB7: =BB20-(BB33+BB46) -> 0 | BC7: =BC20-(BC33+BC46) -> 0 | ... BG7: =BG20-(BG33+BG46) -> 0 | BJ7: =BJ20-(BJ33+BJ46) -> 0 | BK7: =BK20-(BK33+BK46) -> 0 | BL7: =BL20-(BL33+BL46) -> 0 | BM7: =BM20-(BM33+BM46) -> 0 | BN7: =BN20-(BN33+BN46) -> 0 | BO7: =BO20-(BO33+BO46) -> 0 | BP7: =BP20-(BP33+BP46) -> 0 | BQ7: =BQ20-(BQ33+BQ46) -> 0 | ... BU7: =BU20-(BU33+BU46) -> 0 | BX7: =BX20-(BX33+BX46) -> 0 | BY7: =BY20-(BY33+BY46) -> 0 | BZ7: =BZ20-(BZ33+BZ46) -> 0 | CA7: =CA20-(CA33+CA46) -> 0 | CB7: =CB20-(CB33+CB46) -> 0 | CC7: =CC20-(CC33+CC46) -> 0 | CD7: =CD20-(CD33+CD46) -> 0 | CE7: =CE20-(CE33+CE46) -> 0 | ... CI7: =CI20-(CI33+CI46) -> 0 | CL7: =CL20-(CL33+CL46) -> 0 | CM7: =CM20-(CM33+CM46) -> 0 | CN7: =CN20-(CN33+CN46) -> 0 | CO7: =CO20-(CO33+CO46) -> 0 | CP7: =CP20-(CP33+CP46) -> 0 | CQ7: =CQ20-(CQ33+CQ46) -> 0 | CR7: =CR20-(CR33+CR46) -> 0 | CS7: =CS20-(CS33+CS46) -> 0 | ... CW7: =CW20-(CW33+CW46) -> 0 | CZ7: =CZ20-(CZ33+CZ46) -> 0 | DA7: =DA20-(DA33+DA46) -> 0 | DB7: =DB20-(DB33+DB46) -> 0 | DC7: =DC20-(DC33+DC46) -> 0 | DD7: =DD20-(DD33+DD46) -> 0 | DE7: =DE20-(DE33+DE46) -> 0 | DF7: =DF20-(DF33+DF46) -> 0 | DG7: =DG20-(DG33+DG46) -> 0 | ... DK7: =DK20-(DK33+DK46) -> 0
C9: Income | E9: =DATE(E$5,1,1) -> 45658 | F9: =DATE(E$5,2,1) -> 45689 | G9: =DATE(E$5,3,1) -> 45717 | H9: =DATE(E$5,4,1) -> 45748 | I9: =DATE(E$5,5,1) -> 45778 | J9: =DATE(E$5,6,1) -> 45809 | K9: =DATE(E$5,7,1) -> 45839 | L9: =DATE(E$5,8,1) -> 45870 | M9: =DATE(E$5,9,1) -> 45901 | N9: =DATE(E$5,10,1) -> 45931 | O9: =DATE(E$5,11,1) -> 45962 | P9: =DATE(E$5,12,1) -> 45992 | Q9: =$E5 -> 2025 | S9: =DATE(S$5,1,1) -> 46023 | T9: =DATE(S$5,2,1) -> 46054 | U9: =DATE(S$5,3,1) -> 46082 | V9: =DATE(S$5,4,1) -> 46113 | W9: =DATE(S$5,5,1) -> 46143 | X9: =DATE(S$5,6,1) -> 46174 | Y9: =DATE(S$5,7,1) -> 46204 | Z9: =DATE(S$5,8,1) -> 46235 | AA9: =DATE(S$5,9,1) -> 46266 | AB9: =DATE(S$5,10,1) -> 46296 | AC9: =DATE(S$5,11,1) -> 46327 | AD9: =DATE(S$5,12,1) -> 46357 | AE9: =$E5+1 -> 2026 | AG9: =DATE(AG$5,1,1) -> 46388 | AH9: =DATE(AG$5,2,1) -> 46419 | AI9: =DATE(AG$5,3,1) -> 46447 | AJ9: =DATE(AG$5,4,1) -> 46478 | AK9: =DATE(AG$5,5,1) -> 46508 | AL9: =DATE(AG$5,6,1) -> 46539 | AM9: =DATE(AG$5,7,1) -> 46569 | AN9: =DATE(AG$5,8,1) -> 46600 | AO9: =DATE(AG$5,9,1) -> 46631 | AP9: =DATE(AG$5,10,1) -> 46661 | AQ9: =DATE(AG$5,11,1) -> 46692 | AR9: =DATE(AG$5,12,1) -> 46722 | AS9: =$E5+2 -> 2027 | AU9: =DATE(AU$5,1,1) -> 46753 | AV9: =DATE(AU$5,2,1) -> 46784 | AW9: =DATE(AU$5,3,1) -> 46813 | AX9: =DATE(AU$5,4,1) -> 46844 | AY9: =DATE(AU$5,5,1) -> 46874 | AZ9: =DATE(AU$5,6,1) -> 46905 | BA9: =DATE(AU$5,7,1) -> 46935 | BB9: =DATE(AU$5,8,1) -> 46966 | BC9: =DATE(AU$5,9,1) -> 46997 | BD9: =DATE(AU$5,10,1) -> 47027 | BE9: =DATE(AU$5,11,1) -> 47058 | BF9: =DATE(AU$5,12,1) -> 47088 | BG9: =$E5+3 -> 2028 | BI9: =DATE(BI$5,1,1) -> 47119 | BJ9: =DATE(BI$5,2,1) -> 47150 | BK9: =DATE(BI$5,3,1) -> 47178 | BL9: =DATE(BI$5,4,1) -> 47209 | BM9: =DATE(BI$5,5,1) -> 47239 | BN9: =DATE(BI$5,6,1) -> 47270 | BO9: =DATE(BI$5,7,1) -> 47300 | BP9: =DATE(BI$5,8,1) -> 47331 | BQ9: =DATE(BI$5,9,1) -> 47362 | BR9: =DATE(BI$5,10,1) -> 47392 | BS9: =DATE(BI$5,11,1) -> 47423 | BT9: =DATE(BI$5,12,1) -> 47453 | BU9: =$E5+4 -> 2029 | BW9: =DATE(BW$5,1,1) -> 47484 | BX9: =DATE(BW$5,2,1) -> 47515 | BY9: =DATE(BW$5,3,1) -> 47543 | BZ9: =DATE(BW$5,4,1) -> 47574 | CA9: =DATE(BW$5,5,1) -> 47604 | CB9: =DATE(BW$5,6,1) -> 47635 | CC9: =DATE(BW$5,7,1) -> 47665 | CD9: =DATE(BW$5,8,1) -> 47696 | CE9: =DATE(BW$5,9,1) -> 47727 | CF9: =DATE(BW$5,10,1) -> 47757 | CG9: =DATE(BW$5,11,1) -> 47788 | CH9: =DATE(BW$5,12,1) -> 47818 | CI9: =$E5+5 -> 2030 | CK9: =DATE(CK$5,1,1) -> 47849 | CL9: =DATE(CK$5,2,1) -> 47880 | CM9: =DATE(CK$5,3,1) -> 47908 | CN9: =DATE(CK$5,4,1) -> 47939 | CO9: =DATE(CK$5,5,1) -> 47969 | CP9: =DATE(CK$5,6,1) -> 48000 | CQ9: =DATE(CK$5,7,1) -> 48030 | CR9: =DATE(CK$5,8,1) -> 48061 | CS9: =DATE(CK$5,9,1) -> 48092 | CT9: =DATE(CK$5,10,1) -> 48122 | CU9: =DATE(CK$5,11,1) -> 48153 | CV9: =DATE(CK$5,12,1) -> 48183 | CW9: =$E5+6 -> 2031 | CY9: =DATE(CY$5,1,1) -> 48214 | CZ9: =DATE(CY$5,2,1) -> 48245 | DA9: =DATE(CY$5,3,1) -> 48274 | DB9: =DATE(CY$5,4,1) -> 48305 | DC9: =DATE(CY$5,5,1) -> 48335 | DD9: =DATE(CY$5,6,1) -> 48366 | DE9: =DATE(CY$5,7,1) -> 48396 | DF9: =DATE(CY$5,8,1) -> 48427 | DG9: =DATE(CY$5,9,1) -> 48458 | DH9: =DATE(CY$5,10,1) -> 48488 | DI9: =DATE(CY$5,11,1) -> 48519 | DJ9: =DATE(CY$5,12,1) -> 48549 | DK9: =$E5+7 -> 2032
C10: Employment (Net) | E10: 3500 | F10: 3900 | G10: 2000 | H10: 2000 | I10: 2000 | J10: 2000 | K10: 2000 | L10: 2000 | M10: 2000 | N10: 2000 | O10: 2000 | P10: 2000 | Q10: =SUM(E10:P10) -> 27400 | AE10: =SUM(S10:AD10) -> 0 | AS10: =SUM(AG10:AR10) -> 0 | BG10: =SUM(AU10:BF10) -> 0 | BU10: =SUM(BI10:BT10) -> 0 | CI10: =SUM(BW10:CH10) -> 0 | CW10: =SUM(CK10:CV10) -> 0 | DK10: =SUM(CY10:DJ10) -> 0
C11: Side Hustle( Net) | E11: 200 | F11: 200 | G11: 200 | H11: 200 | I11: 200 | J11: 200 | K11: 200 | L11: 200 | M11: 200 | N11: 200 | O11: 200 | P11: 200 | Q11: =SUM(E11:P11) -> 2400 | AE11: =SUM(S11:AD11) -> 0 | AS11: =SUM(AG11:AR11) -> 0 | BG11: =SUM(AU11:BF11) -> 0 | BU11: =SUM(BI11:BT11) -> 0 | CI11: =SUM(BW11:CH11) -> 0 | CW11: =SUM(CK11:CV11) -> 0 | DK11: =SUM(CY11:DJ11) -> 0
C12: Dividends | E12: 100 | F12: 500 | G12: 500 | H12: 500 | I12: 500 | J12: 500 | K12: 500 | L12: 500 | M12: 500 | N12: 500 | O12: 500 | P12: 500 | Q12: =SUM(E12:P12) -> 5600 | AE12: =SUM(S12:AD12) -> 0 | AS12: =SUM(AG12:AR12) -> 0 | BG12: =SUM(AU12:BF12) -> 0 | BU12: =SUM(BI12:BT12) -> 0 | CI12: =SUM(BW12:CH12) -> 0 | CW12: =SUM(CK12:CV12) -> 0 | DK12: =SUM(CY12:DJ12) -> 0
C13: Other | Q13: =SUM(E13:P13) -> 0 | AE13: =SUM(S13:AD13) -> 0 | AS13: =SUM(AG13:AR13) -> 0 | BG13: =SUM(AU13:BF13) -> 0 | BU13: =SUM(BI13:BT13) -> 0 | CI13: =SUM(BW13:CH13) -> 0 | CW13: =SUM(CK13:CV13) -> 0 | DK13: =SUM(CY13:DJ13) -> 0
C14: Enter Income Category… | Q14: =SUM(E14:P14) -> 0 | AE14: =SUM(S14:AD14) -> 0 | AS14: =SUM(AG14:AR14) -> 0 | BG14: =SUM(AU14:BF14) -> 0 | BU14: =SUM(BI14:BT14) -> 0 | CI14: =SUM(BW14:CH14) -> 0 | CW14: =SUM(CK14:CV14) -> 0 | DK14: =SUM(CY14:DJ14) -> 0
C15: Enter Income Category… | Q15: =SUM(E15:P15) -> 0 | AE15: =SUM(S15:AD15) -> 0 | AS15: =SUM(AG15:AR15) -> 0 | BG15: =SUM(AU15:BF15) -> 0 | BU15: =SUM(BI15:BT15) -> 0 | CI15: =SUM(BW15:CH15) -> 0 | CW15: =SUM(CK15:CV15) -> 0 | DK15: =SUM(CY15:DJ15) -> 0
C16: Enter Income Category… | Q16: =SUM(E16:P16) -> 0 | AE16: =SUM(S16:AD16) -> 0 | AS16: =SUM(AG16:AR16) -> 0 | BG16: =SUM(AU16:BF16) -> 0 | BU16: =SUM(BI16:BT16) -> 0 | CI16: =SUM(BW16:CH16) -> 0 | CW16: =SUM(CK16:CV16) -> 0 | DK16: =SUM(CY16:DJ16) -> 0
C17: Enter Income Category… | Q17: =SUM(E17:P17) -> 0 | AE17: =SUM(S17:AD17) -> 0 | AS17: =SUM(AG17:AR17) -> 0 | BG17: =SUM(AU17:BF17) -> 0 | BU17: =SUM(BI17:BT17) -> 0 | CI17: =SUM(BW17:CH17) -> 0 | CW17: =SUM(CK17:CV17) -> 0 | DK17: =SUM(CY17:DJ17) -> 0
C18: Enter Income Category… | Q18: =SUM(E18:P18) -> 0 | AE18: =SUM(S18:AD18) -> 0 | AS18: =SUM(AG18:AR18) -> 0 | BG18: =SUM(AU18:BF18) -> 0 | BU18: =SUM(BI18:BT18) -> 0 | CI18: =SUM(BW18:CH18) -> 0 | CW18: =SUM(CK18:CV18) -> 0 | DK18: =SUM(CY18:DJ18) -> 0
C19: Enter Income Category… | Q19: =SUM(E19:P19) -> 0 | AE19: =SUM(S19:AD19) -> 0 | AS19: =SUM(AG19:AR19) -> 0 | BG19: =SUM(AU19:BF19) -> 0 | BU19: =SUM(BI19:BT19) -> 0 | CI19: =SUM(BW19:CH19) -> 0 | CW19: =SUM(CK19:CV19) -> 0 | DK19: =SUM(CY19:DJ19) -> 0
C20: Total | E20: {=SUM(INDIRECT(ADDRESS(income_min_row,COLUMN())&":" & ADDRESS(income_max_row, COLUMN())))} -> 3800 | F20: {=SUM(INDIRECT(ADDRESS(income_min_row,COLUMN())&":" & ADDRESS(income_max_row, COLUMN())))} -> 4600 | G20: {=SUM(INDIRECT(ADDRESS(income_min_row,COLUMN())&":" & ADDRESS(income_max_row, COLUMN())))} -> 2700 | H20: {=SUM(INDIRECT(ADDRESS(income_min_row,COLUMN())&":" & ADDRESS(income_max_row, COLUMN())))} -> 2700 | I20: {=SUM(INDIRECT(ADDRESS(income_min_row,COLUMN())&":" & ADDRESS(income_max_row, COLUMN())))} -> 2700 | J20: {=SUM(INDIRECT(ADDRESS(income_min_row,COLUMN())&":" & ADDRESS(income_max_row, COLUMN())))} -> 2700 | K20: {=SUM(INDIRECT(ADDRESS(income_min_row,COLUMN())&":" & ADDRESS(income_max_row, COLUMN())))} -> 2700 | L20: {=SUM(INDIRECT(ADDRESS(income_min_row,COLUMN())&":" & ADDRESS(income_max_row, COLUMN())))} -> 2700 | ... Q20: {=SUM(INDIRECT(ADDRESS(income_min_row,COLUMN())&":" & ADDRESS(income_max_row, COLUMN())))} -> 35400 | S20: {=SUM(INDIRECT(ADDRESS(income_min_row,COLUMN())&":" & ADDRESS(income_max_row, COLUMN())))} -> 0 | T20: {=SUM(INDIRECT(ADDRESS(income_min_row,COLUMN())&":" & ADDRESS(income_max_row, COLUMN())))} -> 0 | U20: {=SUM(INDIRECT(ADDRESS(income_min_row,COLUMN())&":" & ADDRESS(income_max_row, COLUMN())))} -> 0 | V20: {=SUM(INDIRECT(ADDRESS(income_min_row,COLUMN())&":" & ADDRESS(income_max_row, COLUMN())))} -> 0 | W20: {=SUM(INDIRECT(ADDRESS(income_min_row,COLUMN())&":" & ADDRESS(income_max_row, COLUMN())))} -> 0 | X20: {=SUM(INDIRECT(ADDRESS(income_min_row,COLUMN())&":" & ADDRESS(income_max_row, COLUMN())))} -> 0 | Y20: {=SUM(INDIRECT(ADDRESS(income_min_row,COLUMN())&":" & ADDRESS(income_max_row, COLUMN())))} -> 0 | Z20: {=SUM(INDIRECT(ADDRESS(income_min_row,COLUMN())&":" & ADDRESS(income_max_row, COLUMN())))} -> 0 | ... AE20: {=SUM(INDIRECT(ADDRESS(income_min_row,COLUMN())&":" & ADDRESS(income_max_row, COLUMN())))} -> 0 | AG20: {=SUM(INDIRECT(ADDRESS(income_min_row,COLUMN())&":" & ADDRESS(income_max_row, COLUMN())))} -> 0 | AH20: {=SUM(INDIRECT(ADDRESS(income_min_row,COLUMN())&":" & ADDRESS(income_max_row, COLUMN())))} -> 0 | AI20: {=SUM(INDIRECT(ADDRESS(income_min_row,COLUMN())&":" & ADDRESS(income_max_row, COLUMN())))} -> 0 | AJ20: {=SUM(INDIRECT(ADDRESS(income_min_row,COLUMN())&":" & ADDRESS(income_max_row, COLUMN())))} -> 0 | AK20: {=SUM(INDIRECT(ADDRESS(income_min_row,COLUMN())&":" & ADDRESS(income_max_row, COLUMN())))} -> 0 | AL20: {=SUM(INDIRECT(ADDRESS(income_min_row,COLUMN())&":" & ADDRESS(income_max_row, COLUMN())))} -> 0 | AM20: {=SUM(INDIRECT(ADDRESS(income_min_row,COLUMN())&":" & ADDRESS(income_max_row, COLUMN())))} -> 0 | AN20: {=SUM(INDIRECT(ADDRESS(income_min_row,COLUMN())&":" & ADDRESS(income_max_row, COLUMN())))} -> 0 | ... AS20: {=SUM(INDIRECT(ADDRESS(income_min_row,COLUMN())&":" & ADDRESS(income_max_row, COLUMN())))} -> 0 | AU20: {=SUM(INDIRECT(ADDRESS(income_min_row,COLUMN())&":" & ADDRESS(income_max_row, COLUMN())))} -> 0 | AV20: {=SUM(INDIRECT(ADDRESS(income_min_row,COLUMN())&":" & ADDRESS(income_max_row, COLUMN())))} -> 0 | AW20: {=SUM(INDIRECT(ADDRESS(income_min_row,COLUMN())&":" & ADDRESS(income_max_row, COLUMN())))} -> 0 | AX20: {=SUM(INDIRECT(ADDRESS(income_min_row,COLUMN())&":" & ADDRESS(income_max_row, COLUMN())))} -> 0 | AY20: {=SUM(INDIRECT(ADDRESS(income_min_row,COLUMN())&":" & ADDRESS(income_max_row, COLUMN())))} -> 0 | AZ20: {=SUM(INDIRECT(ADDRESS(income_min_row,COLUMN())&":" & ADDRESS(income_max_row, COLUMN())))} -> 0 | BA20: {=SUM(INDIRECT(ADDRESS(income_min_row,COLUMN())&":" & ADDRESS(income_max_row, COLUMN())))} -> 0 | BB20: {=SUM(INDIRECT(ADDRESS(income_min_row,COLUMN())&":" & ADDRESS(income_max_row, COLUMN())))} -> 0 | ... BG20: {=SUM(INDIRECT(ADDRESS(income_min_row,COLUMN())&":" & ADDRESS(income_max_row, COLUMN())))} -> 0 | BI20: {=SUM(INDIRECT(ADDRESS(income_min_row,COLUMN())&":" & ADDRESS(income_max_row, COLUMN())))} -> 0 | BJ20: {=SUM(INDIRECT(ADDRESS(income_min_row,COLUMN())&":" & ADDRESS(income_max_row, COLUMN())))} -> 0 | BK20: {=SUM(INDIRECT(ADDRESS(income_min_row,COLUMN())&":" & ADDRESS(income_max_row, COLUMN())))} -> 0 | BL20: {=SUM(INDIRECT(ADDRESS(income_min_row,COLUMN())&":" & ADDRESS(income_max_row, COLUMN())))} -> 0 | BM20: {=SUM(INDIRECT(ADDRESS(income_min_row,COLUMN())&":" & ADDRESS(income_max_row, COLUMN())))} -> 0 | BN20: {=SUM(INDIRECT(ADDRESS(income_min_row,COLUMN())&":" & ADDRESS(income_max_row, COLUMN())))} -> 0 | BO20: {=SUM(INDIRECT(ADDRESS(income_min_row,COLUMN())&":" & ADDRESS(income_max_row, COLUMN())))} -> 0 | BP20: {=SUM(INDIRECT(ADDRESS(income_min_row,COLUMN())&":" & ADDRESS(income_max_row, COLUMN())))} -> 0 | ... BU20: {=SUM(INDIRECT(ADDRESS(income_min_row,COLUMN())&":" & ADDRESS(income_max_row, COLUMN())))} -> 0 | BW20: {=SUM(INDIRECT(ADDRESS(income_min_row,COLUMN())&":" & ADDRESS(income_max_row, COLUMN())))} -> 0 | BX20: {=SUM(INDIRECT(ADDRESS(income_min_row,COLUMN())&":" & ADDRESS(income_max_row, COLUMN())))} -> 0 | BY20: {=SUM(INDIRECT(ADDRESS(income_min_row,COLUMN())&":" & ADDRESS(income_max_row, COLUMN())))} -> 0 | BZ20: {=SUM(INDIRECT(ADDRESS(income_min_row,COLUMN())&":" & ADDRESS(income_max_row, COLUMN())))} -> 0 | CA20: {=SUM(INDIRECT(ADDRESS(income_min_row,COLUMN())&":" & ADDRESS(income_max_row, COLUMN())))} -> 0 | CB20: {=SUM(INDIRECT(ADDRESS(income_min_row,COLUMN())&":" & ADDRESS(income_max_row, COLUMN())))} -> 0 | CC20: {=SUM(INDIRECT(ADDRESS(income_min_row,COLUMN())&":" & ADDRESS(income_max_row, COLUMN())))} -> 0 | CD20: {=SUM(INDIRECT(ADDRESS(income_min_row,COLUMN())&":" & ADDRESS(income_max_row, COLUMN())))} -> 0 | ... CI20: {=SUM(INDIRECT(ADDRESS(income_min_row,COLUMN())&":" & ADDRESS(income_max_row, COLUMN())))} -> 0 | CK20: {=SUM(INDIRECT(ADDRESS(income_min_row,COLUMN())&":" & ADDRESS(income_max_row, COLUMN())))} -> 0 | CL20: {=SUM(INDIRECT(ADDRESS(income_min_row,COLUMN())&":" & ADDRESS(income_max_row, COLUMN())))} -> 0 | CM20: {=SUM(INDIRECT(ADDRESS(income_min_row,COLUMN())&":" & ADDRESS(income_max_row, COLUMN())))} -> 0 | CN20: {=SUM(INDIRECT(ADDRESS(income_min_row,COLUMN())&":" & ADDRESS(income_max_row, COLUMN())))} -> 0 | CO20: {=SUM(INDIRECT(ADDRESS(income_min_row,COLUMN())&":" & ADDRESS(income_max_row, COLUMN())))} -> 0 | CP20: {=SUM(INDIRECT(ADDRESS(income_min_row,COLUMN())&":" & ADDRESS(income_max_row, COLUMN())))} -> 0 | CQ20: {=SUM(INDIRECT(ADDRESS(income_min_row,COLUMN())&":" & ADDRESS(income_max_row, COLUMN())))} -> 0 | CR20: {=SUM(INDIRECT(ADDRESS(income_min_row,COLUMN())&":" & ADDRESS(income_max_row, COLUMN())))} -> 0 | ... CW20: {=SUM(INDIRECT(ADDRESS(income_min_row,COLUMN())&":" & ADDRESS(income_max_row, COLUMN())))} -> 0 | CY20: {=SUM(INDIRECT(ADDRESS(income_min_row,COLUMN())&":" & ADDRESS(income_max_row, COLUMN())))} -> 0 | CZ20: {=SUM(INDIRECT(ADDRESS(income_min_row,COLUMN())&":" & ADDRESS(income_max_row, COLUMN())))} -> 0 | DA20: {=SUM(INDIRECT(ADDRESS(income_min_row,COLUMN())&":" & ADDRESS(income_max_row, COLUMN())))} -> 0 | DB20: {=SUM(INDIRECT(ADDRESS(income_min_row,COLUMN())&":" & ADDRESS(income_max_row, COLUMN())))} -> 0 | DC20: {=SUM(INDIRECT(ADDRESS(income_min_row,COLUMN())&":" & ADDRESS(income_max_row, COLUMN())))} -> 0 | DD20: {=SUM(INDIRECT(ADDRESS(income_min_row,COLUMN())&":" & ADDRESS(income_max_row, COLUMN())))} -> 0 | DE20: {=SUM(INDIRECT(ADDRESS(income_min_row,COLUMN())&":" & ADDRESS(income_max_row, COLUMN())))} -> 0 | DF20: {=SUM(INDIRECT(ADDRESS(income_min_row,COLUMN())&":" & ADDRESS(income_max_row, COLUMN())))} -> 0 | ... DK20: {=SUM(INDIRECT(ADDRESS(income_min_row,COLUMN())&":" & ADDRESS(income_max_row, COLUMN())))} -> 0
C22: Expenses | E22: =DATE(E$5,1,1) -> 45658 | F22: =DATE(E$5,2,1) -> 45689 | G22: =DATE(E$5,3,1) -> 45717 | H22: =DATE(E$5,4,1) -> 45748 | I22: =DATE(E$5,5,1) -> 45778 | J22: =DATE(E$5,6,1) -> 45809 | K22: =DATE(E$5,7,1) -> 45839 | L22: =DATE(E$5,8,1) -> 45870 | M22: =DATE(E$5,9,1) -> 45901 | N22: =DATE(E$5,10,1) -> 45931 | O22: =DATE(E$5,11,1) -> 45962 | P22: =DATE(E$5,12,1) -> 45992 | Q22: =$E5 -> 2025 | S22: =DATE(S$5,1,1) -> 46023 | T22: =DATE(S$5,2,1) -> 46054 | U22: =DATE(S$5,3,1) -> 46082 | V22: =DATE(S$5,4,1) -> 46113 | W22: =DATE(S$5,5,1) -> 46143 | X22: =DATE(S$5,6,1) -> 46174 | Y22: =DATE(S$5,7,1) -> 46204 | Z22: =DATE(S$5,8,1) -> 46235 | AA22: =DATE(S$5,9,1) -> 46266 | AB22: =DATE(S$5,10,1) -> 46296 | AC22: =DATE(S$5,11,1) -> 46327 | AD22: =DATE(S$5,12,1) -> 46357 | AE22: =$E5+1 -> 2026 | AG22: =DATE(AG$5,1,1) -> 46388 | AH22: =DATE(AG$5,2,1) -> 46419 | AI22: =DATE(AG$5,3,1) -> 46447 | AJ22: =DATE(AG$5,4,1) -> 46478 | AK22: =DATE(AG$5,5,1) -> 46508 | AL22: =DATE(AG$5,6,1) -> 46539 | AM22: =DATE(AG$5,7,1) -> 46569 | AN22: =DATE(AG$5,8,1) -> 46600 | AO22: =DATE(AG$5,9,1) -> 46631 | AP22: =DATE(AG$5,10,1) -> 46661 | AQ22: =DATE(AG$5,11,1) -> 46692 | AR22: =DATE(AG$5,12,1) -> 46722 | AS22: =$E5+2 -> 2027 | AU22: =DATE(AU$5,1,1) -> 46753 | AV22: =DATE(AU$5,2,1) -> 46784 | AW22: =DATE(AU$5,3,1) -> 46813 | AX22: =DATE(AU$5,4,1) -> 46844 | AY22: =DATE(AU$5,5,1) -> 46874 | AZ22: =DATE(AU$5,6,1) -> 46905 | BA22: =DATE(AU$5,7,1) -> 46935 | BB22: =DATE(AU$5,8,1) -> 46966 | BC22: =DATE(AU$5,9,1) -> 46997 | BD22: =DATE(AU$5,10,1) -> 47027 | BE22: =DATE(AU$5,11,1) -> 47058 | BF22: =DATE(AU$5,12,1) -> 47088 | BG22: =$E5+3 -> 2028 | BI22: =DATE(BI$5,1,1) -> 47119 | BJ22: =DATE(BI$5,2,1) -> 47150 | BK22: =DATE(BI$5,3,1) -> 47178 | BL22: =DATE(BI$5,4,1) -> 47209 | BM22: =DATE(BI$5,5,1) -> 47239 | BN22: =DATE(BI$5,6,1) -> 47270 | BO22: =DATE(BI$5,7,1) -> 47300 | BP22: =DATE(BI$5,8,1) -> 47331 | BQ22: =DATE(BI$5,9,1) -> 47362 | BR22: =DATE(BI$5,10,1) -> 47392 | BS22: =DATE(BI$5,11,1) -> 47423 | BT22: =DATE(BI$5,12,1) -> 47453 | BU22: =$E5+4 -> 2029 | BW22: =DATE(BW$5,1,1) -> 47484 | BX22: =DATE(BW$5,2,1) -> 47515 | BY22: =DATE(BW$5,3,1) -> 47543 | BZ22: =DATE(BW$5,4,1) -> 47574 | CA22: =DATE(BW$5,5,1) -> 47604 | CB22: =DATE(BW$5,6,1) -> 47635 | CC22: =DATE(BW$5,7,1) -> 47665 | CD22: =DATE(BW$5,8,1) -> 47696 | CE22: =DATE(BW$5,9,1) -> 47727 | CF22: =DATE(BW$5,10,1) -> 47757 | CG22: =DATE(BW$5,11,1) -> 47788 | CH22: =DATE(BW$5,12,1) -> 47818 | CI22: =$E5+5 -> 2030 | CK22: =DATE(CK$5,1,1) -> 47849 | CL22: =DATE(CK$5,2,1) -> 47880 | CM22: =DATE(CK$5,3,1) -> 47908 | CN22: =DATE(CK$5,4,1) -> 47939 | CO22: =DATE(CK$5,5,1) -> 47969 | CP22: =DATE(CK$5,6,1) -> 48000 | CQ22: =DATE(CK$5,7,1) -> 48030 | CR22: =DATE(CK$5,8,1) -> 48061 | CS22: =DATE(CK$5,9,1) -> 48092 | CT22: =DATE(CK$5,10,1) -> 48122 | CU22: =DATE(CK$5,11,1) -> 48153 | CV22: =DATE(CK$5,12,1) -> 48183 | CW22: =$E5+6 -> 2031 | CY22: =DATE(CY$5,1,1) -> 48214 | CZ22: =DATE(CY$5,2,1) -> 48245 | DA22: =DATE(CY$5,3,1) -> 48274 | DB22: =DATE(CY$5,4,1) -> 48305 | DC22: =DATE(CY$5,5,1) -> 48335 | DD22: =DATE(CY$5,6,1) -> 48366 | DE22: =DATE(CY$5,7,1) -> 48396 | DF22: =DATE(CY$5,8,1) -> 48427 | DG22: =DATE(CY$5,9,1) -> 48458 | DH22: =DATE(CY$5,10,1) -> 48488 | DI22: =DATE(CY$5,11,1) -> 48519 | DJ22: =DATE(CY$5,12,1) -> 48549 | DK22: =$E5+7 -> 2032
C23: Housing(Rent) | E23: 1200 | F23: 1200 | G23: 1200 | H23: 1200 | I23: 1200 | J23: 1200 | K23: 1200 | L23: 1200 | M23: 1200 | N23: 1200 | O23: 1200 | P23: 1200 | Q23: =SUM(E23:P23) -> 14400 | AE23: =SUM(S23:AD23) -> 0 | AS23: =SUM(AG23:AR23) -> 0 | BG23: =SUM(AU23:BF23) -> 0 | BU23: =SUM(BI23:BT23) -> 0 | CI23: =SUM(BW23:CH23) -> 0 | CW23: =SUM(CK23:CV23) -> 0 | DK23: =SUM(CY23:DJ23) -> 0
C24: Utilities (house media fees) | E24: 200 | F24: 200 | G24: 200 | H24: 200 | I24: 200 | J24: 200 | K24: 200 | L24: 200 | M24: 200 | N24: 400 | O24: 200 | Q24: =SUM(E24:P24) -> 2400 | AE24: =SUM(S24:AD24) -> 0 | AS24: =SUM(AG24:AR24) -> 0 | BG24: =SUM(AU24:BF24) -> 0 | BU24: =SUM(BI24:BT24) -> 0 | CI24: =SUM(BW24:CH24) -> 0 | CW24: =SUM(CK24:CV24) -> 0 | DK24: =SUM(CY24:DJ24) -> 0
C25: Groceries | E25: 800 | F25: 800 | G25: 800 | H25: 800 | I25: 800 | J25: 800 | K25: 800 | L25: 800 | M25: 800 | N25: 800 | Q25: =SUM(E25:P25) -> 8000 | AE25: =SUM(S25:AD25) -> 0 | AS25: =SUM(AG25:AR25) -> 0 | BG25: =SUM(AU25:BF25) -> 0 | BU25: =SUM(BI25:BT25) -> 0 | CI25: =SUM(BW25:CH25) -> 0 | CW25: =SUM(CK25:CV25) -> 0 | DK25: =SUM(CY25:DJ25) -> 0
C26: Transportation | E26: 100 | F26: 100 | G26: 100 | H26: 100 | I26: 100 | J26: 100 | K26: 100 | L26: 100 | M26: 100 | N26: 100 | O26: 100 | Q26: =SUM(E26:P26) -> 1100 | AE26: =SUM(S26:AD26) -> 0 | AS26: =SUM(AG26:AR26) -> 0 | BG26: =SUM(AU26:BF26) -> 0 | BU26: =SUM(BI26:BT26) -> 0 | CI26: =SUM(BW26:CH26) -> 0 | CW26: =SUM(CK26:CV26) -> 0 | DK26: =SUM(CY26:DJ26) -> 0
C27: Family Tax | E27: 200 | F27: 200 | G27: 200 | H27: 200 | I27: 200 | J27: 200 | K27: 200 | L27: 200 | M27: 200 | N27: 200 | Q27: =SUM(E27:P27) -> 2000 | AE27: =SUM(S27:AD27) -> 0 | AS27: =SUM(AG27:AR27) -> 0 | BG27: =SUM(AU27:BF27) -> 0 | BU27: =SUM(BI27:BT27) -> 0 | CI27: =SUM(BW27:CH27) -> 0 | CW27: =SUM(CK27:CV27) -> 0 | DK27: =SUM(CY27:DJ27) -> 0
C28: Fun & Vacation | E28: 300 | F28: 300 | G28: 200 | H28: 200 | I28: 200 | J28: 200 | K28: 200 | L28: 200 | M28: 200 | N28: 0 | O28: 0 | P28: 0 | Q28: =SUM(E28:P28) -> 2000 | AE28: =SUM(S28:AD28) -> 0 | AS28: =SUM(AG28:AR28) -> 0 | BG28: =SUM(AU28:BF28) -> 0 | BU28: =SUM(BI28:BT28) -> 0 | CI28: =SUM(BW28:CH28) -> 0 | CW28: =SUM(CK28:CV28) -> 0 | DK28: =SUM(CY28:DJ28) -> 0
C29: Edu & Work tools | Q29: =SUM(E29:P29) -> 0 | AE29: =SUM(S29:AD29) -> 0 | AS29: =SUM(AG29:AR29) -> 0 | BG29: =SUM(AU29:BF29) -> 0 | BU29: =SUM(BI29:BT29) -> 0 | CI29: =SUM(BW29:CH29) -> 0 | CW29: =SUM(CK29:CV29) -> 0 | DK29: =SUM(CY29:DJ29) -> 0
C30: Health & Wellnes | Q30: =SUM(E30:P30) -> 0 | AE30: =SUM(S30:AD30) -> 0 | AS30: =SUM(AG30:AR30) -> 0 | BG30: =SUM(AU30:BF30) -> 0 | BU30: =SUM(BI30:BT30) -> 0 | CI30: =SUM(BW30:CH30) -> 0 | CW30: =SUM(CK30:CV30) -> 0 | DK30: =SUM(CY30:DJ30) -> 0
C31: Enter Expense Catergory | Q31: =SUM(E31:P31) -> 0 | AE31: =SUM(S31:AD31) -> 0 | AS31: =SUM(AG31:AR31) -> 0 | BG31: =SUM(AU31:BF31) -> 0 | BU31: =SUM(BI31:BT31) -> 0 | CI31: =SUM(BW31:CH31) -> 0 | CW31: =SUM(CK31:CV31) -> 0 | DK31: =SUM(CY31:DJ31) -> 0
C32: Enter Expense Catergory | E32: 0 | F32: 0 | Q32: =SUM(E32:P32) -> 0 | AE32: =SUM(S32:AD32) -> 0 | AS32: =SUM(AG32:AR32) -> 0 | BG32: =SUM(AU32:BF32) -> 0 | BU32: =SUM(BI32:BT32) -> 0 | CI32: =SUM(BW32:CH32) -> 0 | CW32: =SUM(CK32:CV32) -> 0 | DK32: =SUM(CY32:DJ32) -> 0
C33: Total | E33: {=SUM(INDIRECT(ADDRESS(expenses_min_row,COLUMN())&":" & ADDRESS(expenses_max_row, COLUMN())))} -> 2800 | F33: {=SUM(INDIRECT(ADDRESS(expenses_min_row,COLUMN())&":" & ADDRESS(expenses_max_row, COLUMN())))} -> 2800 | G33: {=SUM(INDIRECT(ADDRESS(expenses_min_row,COLUMN())&":" & ADDRESS(expenses_max_row, COLUMN())))} -> 2700 | H33: {=SUM(INDIRECT(ADDRESS(expenses_min_row,COLUMN())&":" & ADDRESS(expenses_max_row, COLUMN())))} -> 2700 | I33: {=SUM(INDIRECT(ADDRESS(expenses_min_row,COLUMN())&":" & ADDRESS(expenses_max_row, COLUMN())))} -> 2700 | J33: {=SUM(INDIRECT(ADDRESS(expenses_min_row,COLUMN())&":" & ADDRESS(expenses_max_row, COLUMN())))} -> 2700 | K33: {=SUM(INDIRECT(ADDRESS(expenses_min_row,COLUMN())&":" & ADDRESS(expenses_max_row, COLUMN())))} -> 2700 | L33: {=SUM(INDIRECT(ADDRESS(expenses_min_row,COLUMN())&":" & ADDRESS(expenses_max_row, COLUMN())))} -> 2700 | ... Q33: {=SUM(INDIRECT(ADDRESS(expenses_min_row,COLUMN())&":" & ADDRESS(expenses_max_row, COLUMN())))} -> 29900 | S33: {=SUM(INDIRECT(ADDRESS(expenses_min_row,COLUMN())&":" & ADDRESS(expenses_max_row, COLUMN())))} -> 0 | T33: {=SUM(INDIRECT(ADDRESS(expenses_min_row,COLUMN())&":" & ADDRESS(expenses_max_row, COLUMN())))} -> 0 | U33: {=SUM(INDIRECT(ADDRESS(expenses_min_row,COLUMN())&":" & ADDRESS(expenses_max_row, COLUMN())))} -> 0 | V33: {=SUM(INDIRECT(ADDRESS(expenses_min_row,COLUMN())&":" & ADDRESS(expenses_max_row, COLUMN())))} -> 0 | W33: {=SUM(INDIRECT(ADDRESS(expenses_min_row,COLUMN())&":" & ADDRESS(expenses_max_row, COLUMN())))} -> 0 | X33: {=SUM(INDIRECT(ADDRESS(expenses_min_row,COLUMN())&":" & ADDRESS(expenses_max_row, COLUMN())))} -> 0 | Y33: {=SUM(INDIRECT(ADDRESS(expenses_min_row,COLUMN())&":" & ADDRESS(expenses_max_row, COLUMN())))} -> 0 | Z33: {=SUM(INDIRECT(ADDRESS(expenses_min_row,COLUMN())&":" & ADDRESS(expenses_max_row, COLUMN())))} -> 0 | ... AE33: {=SUM(INDIRECT(ADDRESS(expenses_min_row,COLUMN())&":" & ADDRESS(expenses_max_row, COLUMN())))} -> 0 | AG33: {=SUM(INDIRECT(ADDRESS(expenses_min_row,COLUMN())&":" & ADDRESS(expenses_max_row, COLUMN())))} -> 0 | AH33: {=SUM(INDIRECT(ADDRESS(expenses_min_row,COLUMN())&":" & ADDRESS(expenses_max_row, COLUMN())))} -> 0 | AI33: {=SUM(INDIRECT(ADDRESS(expenses_min_row,COLUMN())&":" & ADDRESS(expenses_max_row, COLUMN())))} -> 0 | AJ33: {=SUM(INDIRECT(ADDRESS(expenses_min_row,COLUMN())&":" & ADDRESS(expenses_max_row, COLUMN())))} -> 0 | AK33: {=SUM(INDIRECT(ADDRESS(expenses_min_row,COLUMN())&":" & ADDRESS(expenses_max_row, COLUMN())))} -> 0 | AL33: {=SUM(INDIRECT(ADDRESS(expenses_min_row,COLUMN())&":" & ADDRESS(expenses_max_row, COLUMN())))} -> 0 | AM33: {=SUM(INDIRECT(ADDRESS(expenses_min_row,COLUMN())&":" & ADDRESS(expenses_max_row, COLUMN())))} -> 0 | AN33: {=SUM(INDIRECT(ADDRESS(expenses_min_row,COLUMN())&":" & ADDRESS(expenses_max_row, COLUMN())))} -> 0 | ... AS33: {=SUM(INDIRECT(ADDRESS(expenses_min_row,COLUMN())&":" & ADDRESS(expenses_max_row, COLUMN())))} -> 0 | AU33: {=SUM(INDIRECT(ADDRESS(expenses_min_row,COLUMN())&":" & ADDRESS(expenses_max_row, COLUMN())))} -> 0 | AV33: {=SUM(INDIRECT(ADDRESS(expenses_min_row,COLUMN())&":" & ADDRESS(expenses_max_row, COLUMN())))} -> 0 | AW33: {=SUM(INDIRECT(ADDRESS(expenses_min_row,COLUMN())&":" & ADDRESS(expenses_max_row, COLUMN())))} -> 0 | AX33: {=SUM(INDIRECT(ADDRESS(expenses_min_row,COLUMN())&":" & ADDRESS(expenses_max_row, COLUMN())))} -> 0 | AY33: {=SUM(INDIRECT(ADDRESS(expenses_min_row,COLUMN())&":" & ADDRESS(expenses_max_row, COLUMN())))} -> 0 | AZ33: {=SUM(INDIRECT(ADDRESS(expenses_min_row,COLUMN())&":" & ADDRESS(expenses_max_row, COLUMN())))} -> 0 | BA33: {=SUM(INDIRECT(ADDRESS(expenses_min_row,COLUMN())&":" & ADDRESS(expenses_max_row, COLUMN())))} -> 0 | BB33: {=SUM(INDIRECT(ADDRESS(expenses_min_row,COLUMN())&":" & ADDRESS(expenses_max_row, COLUMN())))} -> 0 | ... BG33: {=SUM(INDIRECT(ADDRESS(expenses_min_row,COLUMN())&":" & ADDRESS(expenses_max_row, COLUMN())))} -> 0 | BI33: {=SUM(INDIRECT(ADDRESS(expenses_min_row,COLUMN())&":" & ADDRESS(expenses_max_row, COLUMN())))} -> 0 | BJ33: {=SUM(INDIRECT(ADDRESS(expenses_min_row,COLUMN())&":" & ADDRESS(expenses_max_row, COLUMN())))} -> 0 | BK33: {=SUM(INDIRECT(ADDRESS(expenses_min_row,COLUMN())&":" & ADDRESS(expenses_max_row, COLUMN())))} -> 0 | BL33: {=SUM(INDIRECT(ADDRESS(expenses_min_row,COLUMN())&":" & ADDRESS(expenses_max_row, COLUMN())))} -> 0 | BM33: {=SUM(INDIRECT(ADDRESS(expenses_min_row,COLUMN())&":" & ADDRESS(expenses_max_row, COLUMN())))} -> 0 | BN33: {=SUM(INDIRECT(ADDRESS(expenses_min_row,COLUMN())&":" & ADDRESS(expenses_max_row, COLUMN())))} -> 0 | BO33: {=SUM(INDIRECT(ADDRESS(expenses_min_row,COLUMN())&":" & ADDRESS(expenses_max_row, COLUMN())))} -> 0 | BP33: {=SUM(INDIRECT(ADDRESS(expenses_min_row,COLUMN())&":" & ADDRESS(expenses_max_row, COLUMN())))} -> 0 | ... BU33: {=SUM(INDIRECT(ADDRESS(expenses_min_row,COLUMN())&":" & ADDRESS(expenses_max_row, COLUMN())))} -> 0 | BW33: {=SUM(INDIRECT(ADDRESS(expenses_min_row,COLUMN())&":" & ADDRESS(expenses_max_row, COLUMN())))} -> 0 | BX33: {=SUM(INDIRECT(ADDRESS(expenses_min_row,COLUMN())&":" & ADDRESS(expenses_max_row, COLUMN())))} -> 0 | BY33: {=SUM(INDIRECT(ADDRESS(expenses_min_row,COLUMN())&":" & ADDRESS(expenses_max_row, COLUMN())))} -> 0 | BZ33: {=SUM(INDIRECT(ADDRESS(expenses_min_row,COLUMN())&":" & ADDRESS(expenses_max_row, COLUMN())))} -> 0 | CA33: {=SUM(INDIRECT(ADDRESS(expenses_min_row,COLUMN())&":" & ADDRESS(expenses_max_row, COLUMN())))} -> 0 | CB33: {=SUM(INDIRECT(ADDRESS(expenses_min_row,COLUMN())&":" & ADDRESS(expenses_max_row, COLUMN())))} -> 0 | CC33: {=SUM(INDIRECT(ADDRESS(expenses_min_row,COLUMN())&":" & ADDRESS(expenses_max_row, COLUMN())))} -> 0 | CD33: {=SUM(INDIRECT(ADDRESS(expenses_min_row,COLUMN())&":" & ADDRESS(expenses_max_row, COLUMN())))} -> 0 | ... CI33: {=SUM(INDIRECT(ADDRESS(expenses_min_row,COLUMN())&":" & ADDRESS(expenses_max_row, COLUMN())))} -> 0 | CK33: {=SUM(INDIRECT(ADDRESS(expenses_min_row,COLUMN())&":" & ADDRESS(expenses_max_row, COLUMN())))} -> 0 | CL33: {=SUM(INDIRECT(ADDRESS(expenses_min_row,COLUMN())&":" & ADDRESS(expenses_max_row, COLUMN())))} -> 0 | CM33: {=SUM(INDIRECT(ADDRESS(expenses_min_row,COLUMN())&":" & ADDRESS(expenses_max_row, COLUMN())))} -> 0 | CN33: {=SUM(INDIRECT(ADDRESS(expenses_min_row,COLUMN())&":" & ADDRESS(expenses_max_row, COLUMN())))} -> 0 | CO33: {=SUM(INDIRECT(ADDRESS(expenses_min_row,COLUMN())&":" & ADDRESS(expenses_max_row, COLUMN())))} -> 0 | CP33: {=SUM(INDIRECT(ADDRESS(expenses_min_row,COLUMN())&":" & ADDRESS(expenses_max_row, COLUMN())))} -> 0 | CQ33: {=SUM(INDIRECT(ADDRESS(expenses_min_row,COLUMN())&":" & ADDRESS(expenses_max_row, COLUMN())))} -> 0 | CR33: {=SUM(INDIRECT(ADDRESS(expenses_min_row,COLUMN())&":" & ADDRESS(expenses_max_row, COLUMN())))} -> 0 | ... CW33: {=SUM(INDIRECT(ADDRESS(expenses_min_row,COLUMN())&":" & ADDRESS(expenses_max_row, COLUMN())))} -> 0 | CY33: {=SUM(INDIRECT(ADDRESS(expenses_min_row,COLUMN())&":" & ADDRESS(expenses_max_row, COLUMN())))} -> 0 | CZ33: {=SUM(INDIRECT(ADDRESS(expenses_min_row,COLUMN())&":" & ADDRESS(expenses_max_row, COLUMN())))} -> 0 | DA33: {=SUM(INDIRECT(ADDRESS(expenses_min_row,COLUMN())&":" & ADDRESS(expenses_max_row, COLUMN())))} -> 0 | DB33: {=SUM(INDIRECT(ADDRESS(expenses_min_row,COLUMN())&":" & ADDRESS(expenses_max_row, COLUMN())))} -> 0 | DC33: {=SUM(INDIRECT(ADDRESS(expenses_min_row,COLUMN())&":" & ADDRESS(expenses_max_row, COLUMN())))} -> 0 | DD33: {=SUM(INDIRECT(ADDRESS(expenses_min_row,COLUMN())&":" & ADDRESS(expenses_max_row, COLUMN())))} -> 0 | DE33: {=SUM(INDIRECT(ADDRESS(expenses_min_row,COLUMN())&":" & ADDRESS(expenses_max_row, COLUMN())))} -> 0 | DF33: {=SUM(INDIRECT(ADDRESS(expenses_min_row,COLUMN())&":" & ADDRESS(expenses_max_row, COLUMN())))} -> 0 | ... DK33: {=SUM(INDIRECT(ADDRESS(expenses_min_row,COLUMN())&":" & ADDRESS(expenses_max_row, COLUMN())))} -> 0
C35: Savings | E35: =DATE(E$5,1,1) -> 45658 | F35: =DATE(E$5,2,1) -> 45689 | G35: =DATE(E$5,3,1) -> 45717 | H35: =DATE(E$5,4,1) -> 45748 | I35: =DATE(E$5,5,1) -> 45778 | J35: =DATE(E$5,6,1) -> 45809 | K35: =DATE(E$5,7,1) -> 45839 | L35: =DATE(E$5,8,1) -> 45870 | M35: =DATE(E$5,9,1) -> 45901 | N35: =DATE(E$5,10,1) -> 45931 | O35: =DATE(E$5,11,1) -> 45962 | P35: =DATE(E$5,12,1) -> 45992 | Q35: =$E5 -> 2025 | S35: =DATE(S$5,1,1) -> 46023 | T35: =DATE(S$5,2,1) -> 46054 | U35: =DATE(S$5,3,1) -> 46082 | V35: =DATE(S$5,4,1) -> 46113 | W35: =DATE(S$5,5,1) -> 46143 | X35: =DATE(S$5,6,1) -> 46174 | Y35: =DATE(S$5,7,1) -> 46204 | Z35: =DATE(S$5,8,1) -> 46235 | AA35: =DATE(S$5,9,1) -> 46266 | AB35: =DATE(S$5,10,1) -> 46296 | AC35: =DATE(S$5,11,1) -> 46327 | AD35: =DATE(S$5,12,1) -> 46357 | AE35: =$E5+1 -> 2026 | AG35: =DATE(AG$5,1,1) -> 46388 | AH35: =DATE(AG$5,2,1) -> 46419 | AI35: =DATE(AG$5,3,1) -> 46447 | AJ35: =DATE(AG$5,4,1) -> 46478 | AK35: =DATE(AG$5,5,1) -> 46508 | AL35: =DATE(AG$5,6,1) -> 46539 | AM35: =DATE(AG$5,7,1) -> 46569 | AN35: =DATE(AG$5,8,1) -> 46600 | AO35: =DATE(AG$5,9,1) -> 46631 | AP35: =DATE(AG$5,10,1) -> 46661 | AQ35: =DATE(AG$5,11,1) -> 46692 | AR35: =DATE(AG$5,12,1) -> 46722 | AS35: =$E5+2 -> 2027 | AU35: =DATE(AU$5,1,1) -> 46753 | AV35: =DATE(AU$5,2,1) -> 46784 | AW35: =DATE(AU$5,3,1) -> 46813 | AX35: =DATE(AU$5,4,1) -> 46844 | AY35: =DATE(AU$5,5,1) -> 46874 | AZ35: =DATE(AU$5,6,1) -> 46905 | BA35: =DATE(AU$5,7,1) -> 46935 | BB35: =DATE(AU$5,8,1) -> 46966 | BC35: =DATE(AU$5,9,1) -> 46997 | BD35: =DATE(AU$5,10,1) -> 47027 | BE35: =DATE(AU$5,11,1) -> 47058 | BF35: =DATE(AU$5,12,1) -> 47088 | BG35: =$E5+3 -> 2028 | BI35: =DATE(BI$5,1,1) -> 47119 | BJ35: =DATE(BI$5,2,1) -> 47150 | BK35: =DATE(BI$5,3,1) -> 47178 | BL35: =DATE(BI$5,4,1) -> 47209 | BM35: =DATE(BI$5,5,1) -> 47239 | BN35: =DATE(BI$5,6,1) -> 47270 | BO35: =DATE(BI$5,7,1) -> 47300 | BP35: =DATE(BI$5,8,1) -> 47331 | BQ35: =DATE(BI$5,9,1) -> 47362 | BR35: =DATE(BI$5,10,1) -> 47392 | BS35: =DATE(BI$5,11,1) -> 47423 | BT35: =DATE(BI$5,12,1) -> 47453 | BU35: =$E5+4 -> 2029 | BW35: =DATE(BW$5,1,1) -> 47484 | BX35: =DATE(BW$5,2,1) -> 47515 | BY35: =DATE(BW$5,3,1) -> 47543 | BZ35: =DATE(BW$5,4,1) -> 47574 | CA35: =DATE(BW$5,5,1) -> 47604 | CB35: =DATE(BW$5,6,1) -> 47635 | CC35: =DATE(BW$5,7,1) -> 47665 | CD35: =DATE(BW$5,8,1) -> 47696 | CE35: =DATE(BW$5,9,1) -> 47727 | CF35: =DATE(BW$5,10,1) -> 47757 | CG35: =DATE(BW$5,11,1) -> 47788 | CH35: =DATE(BW$5,12,1) -> 47818 | CI35: =$E5+5 -> 2030 | CK35: =DATE(CK$5,1,1) -> 47849 | CL35: =DATE(CK$5,2,1) -> 47880 | CM35: =DATE(CK$5,3,1) -> 47908 | CN35: =DATE(CK$5,4,1) -> 47939 | CO35: =DATE(CK$5,5,1) -> 47969 | CP35: =DATE(CK$5,6,1) -> 48000 | CQ35: =DATE(CK$5,7,1) -> 48030 | CR35: =DATE(CK$5,8,1) -> 48061 | CS35: =DATE(CK$5,9,1) -> 48092 | CT35: =DATE(CK$5,10,1) -> 48122 | CU35: =DATE(CK$5,11,1) -> 48153 | CV35: =DATE(CK$5,12,1) -> 48183 | CW35: =$E5+6 -> 2031 | CY35: =DATE(CY$5,1,1) -> 48214 | CZ35: =DATE(CY$5,2,1) -> 48245 | DA35: =DATE(CY$5,3,1) -> 48274 | DB35: =DATE(CY$5,4,1) -> 48305 | DC35: =DATE(CY$5,5,1) -> 48335 | DD35: =DATE(CY$5,6,1) -> 48366 | DE35: =DATE(CY$5,7,1) -> 48396 | DF35: =DATE(CY$5,8,1) -> 48427 | DG35: =DATE(CY$5,9,1) -> 48458 | DH35: =DATE(CY$5,10,1) -> 48488 | DI35: =DATE(CY$5,11,1) -> 48519 | DJ35: =DATE(CY$5,12,1) -> 48549 | DK35: =$E5+7 -> 2032
C36: Emergency Fund | E36: 500 | F36: 500 | G36: 0 | O36: 1200 | P36: 1500 | Q36: =SUM(E36:P36) -> 3700 | AE36: =SUM(S36:AD36) -> 0 | AS36: =SUM(AG36:AR36) -> 0 | BG36: =SUM(AU36:BF36) -> 0 | BU36: =SUM(BI36:BT36) -> 0 | CI36: =SUM(BW36:CH36) -> 0 | CW36: =SUM(CK36:CV36) -> 0 | DK36: =SUM(CY36:DJ36) -> 0
C37: Rent(saving) | E37: 0 | F37: 1000 | G37: 0 | Q37: =SUM(E37:P37) -> 1000 | AE37: =SUM(S37:AD37) -> 0 | AS37: =SUM(AG37:AR37) -> 0 | BG37: =SUM(AU37:BF37) -> 0 | BU37: =SUM(BI37:BT37) -> 0 | CI37: =SUM(BW37:CH37) -> 0 | CW37: =SUM(CK37:CV37) -> 0 | DK37: =SUM(CY37:DJ37) -> 0
C38: Stock Portfolio | E38: 500 | F38: 300 | Q38: =SUM(E38:P38) -> 800 | AE38: =SUM(S38:AD38) -> 0 | AS38: =SUM(AG38:AR38) -> 0 | BG38: =SUM(AU38:BF38) -> 0 | BU38: =SUM(BI38:BT38) -> 0 | CI38: =SUM(BW38:CH38) -> 0 | CW38: =SUM(CK38:CV38) -> 0 | DK38: =SUM(CY38:DJ38) -> 0
C39: Sinking Fund | Q39: =SUM(E39:P39) -> 0 | AE39: =SUM(S39:AD39) -> 0 | AS39: =SUM(AG39:AR39) -> 0 | BG39: =SUM(AU39:BF39) -> 0 | BU39: =SUM(BI39:BT39) -> 0 | CI39: =SUM(BW39:CH39) -> 0 | CW39: =SUM(CK39:CV39) -> 0 | DK39: =SUM(CY39:DJ39) -> 0
C40: Debt Repayment | Q40: =SUM(E40:P40) -> 0 | AE40: =SUM(S40:AD40) -> 0 | AS40: =SUM(AG40:AR40) -> 0 | BG40: =SUM(AU40:BF40) -> 0 | BU40: =SUM(BI40:BT40) -> 0 | CI40: =SUM(BW40:CH40) -> 0 | CW40: =SUM(CK40:CV40) -> 0 | DK40: =SUM(CY40:DJ40) -> 0
C41: Enter Savings Catergory | Q41: =SUM(E41:P41) -> 0 | AE41: =SUM(S41:AD41) -> 0 | AS41: =SUM(AG41:AR41) -> 0 | BG41: =SUM(AU41:BF41) -> 0 | BU41: =SUM(BI41:BT41) -> 0 | CI41: =SUM(BW41:CH41) -> 0 | CW41: =SUM(CK41:CV41) -> 0 | DK41: =SUM(CY41:DJ41) -> 0
C42: Enter Savings Catergory | Q42: =SUM(E42:P42) -> 0 | AE42: =SUM(S42:AD42) -> 0 | AS42: =SUM(AG42:AR42) -> 0 | BG42: =SUM(AU42:BF42) -> 0 | BU42: =SUM(BI42:BT42) -> 0 | CI42: =SUM(BW42:CH42) -> 0 | CW42: =SUM(CK42:CV42) -> 0 | DK42: =SUM(CY42:DJ42) -> 0
C43: Enter Savings Catergory | Q43: =SUM(E43:P43) -> 0 | AE43: =SUM(S43:AD43) -> 0 | AS43: =SUM(AG43:AR43) -> 0 | BG43: =SUM(AU43:BF43) -> 0 | BU43: =SUM(BI43:BT43) -> 0 | CI43: =SUM(BW43:CH43) -> 0 | CW43: =SUM(CK43:CV43) -> 0 | DK43: =SUM(CY43:DJ43) -> 0
C44: Enter Savings Catergory | Q44: =SUM(E44:P44) -> 0 | AE44: =SUM(S44:AD44) -> 0 | AS44: =SUM(AG44:AR44) -> 0 | BG44: =SUM(AU44:BF44) -> 0 | BU44: =SUM(BI44:BT44) -> 0 | CI44: =SUM(BW44:CH44) -> 0 | CW44: =SUM(CK44:CV44) -> 0 | DK44: =SUM(CY44:DJ44) -> 0
C45: Enter Savings Catergory | Q45: =SUM(E45:P45) -> 0 | AE45: =SUM(S45:AD45) -> 0 | AS45: =SUM(AG45:AR45) -> 0 | BG45: =SUM(AU45:BF45) -> 0 | BU45: =SUM(BI45:BT45) -> 0 | CI45: =SUM(BW45:CH45) -> 0 | CW45: =SUM(CK45:CV45) -> 0 | DK45: =SUM(CY45:DJ45) -> 0
...

Sheet Budget Tracking
A1: Budget Tracking
C11: Date | D11: Type | E11: Category | F11: Amount | G11: Details | H11: Balance | I11: Effective Date | K11: New budget categories cannot be introduced in this sheet, as the categories are dependent of what is provided in the budget planning sheet.
C12: 45775 | D12: Income | E12: Employment (Net) | F12: 3500 | H12: {=SUMPRODUCT(Tracking[Amount], --(Tracking[Date]<=Tracking[[#This Row],[Date]]), (Tracking[Type]<>"Income")*(-1) +(Tracking[Type]="Income"))} -> 3500 | I12: =IF(AND(Tracking[[#This Row],[Type]]="Income", shift_late_income_status="Active", DAY(Tracking[[#This Row],[Date]])>=shift_late_income_starting_day), DATE(YEAR(Tracking[[#This Row],[Date]]),MONTH(Tracking[[#This Row],[Date]])+1,1), Tracking[[#This Row],[Date]]) -> 45778
C13: 45779 | D13: Expenses | E13: Groceries | F13: 400 | H13: {=SUMPRODUCT(Tracking[Amount], --(Tracking[Date]<=Tracking[[#This Row],[Date]]), (Tracking[Type]<>"Income")*(-1) +(Tracking[Type]="Income"))} -> 3100 | I13: =IF(AND(Tracking[[#This Row],[Type]]="Income", shift_late_income_status="Active", DAY(Tracking[[#This Row],[Date]])>=shift_late_income_starting_day), DATE(YEAR(Tracking[[#This Row],[Date]]),MONTH(Tracking[[#This Row],[Date]])+1,1), Tracking[[#This Row],[Date]]) -> 45779
C14: 45780 | D14: Expenses | E14: Utilities (house media fees) | F14: 1000 | H14: {=SUMPRODUCT(Tracking[Amount], --(Tracking[Date]<=Tracking[[#This Row],[Date]]), (Tracking[Type]<>"Income")*(-1) +(Tracking[Type]="Income"))} -> 2100 | I14: =IF(AND(Tracking[[#This Row],[Type]]="Income", shift_late_income_status="Active", DAY(Tracking[[#This Row],[Date]])>=shift_late_income_starting_day), DATE(YEAR(Tracking[[#This Row],[Date]]),MONTH(Tracking[[#This Row],[Date]])+1,1), Tracking[[#This Row],[Date]]) -> 45780 | K14: Adding a New Row to the Budget/Expense table
C15: 45781 | D15: Savings | E15: Emergency Fund | F15: 100 | H15: {=SUMPRODUCT(Tracking[Amount], --(Tracking[Date]<=Tracking[[#This Row],[Date]]), (Tracking[Type]<>"Income")*(-1) +(Tracking[Type]="Income"))} -> 2000 | I15: =IF(AND(Tracking[[#This Row],[Type]]="Income", shift_late_income_status="Active", DAY(Tracking[[#This Row],[Date]])>=shift_late_income_starting_day), DATE(YEAR(Tracking[[#This Row],[Date]]),MONTH(Tracking[[#This Row],[Date]])+1,1), Tracking[[#This Row],[Date]]) -> 45781 | K15: Option 1: - Quick Add(Recommended) 1. Click the first empty cell below the table under the DATE column. 2. Enter the date of entry and press TAB to move across. The table should expand automatically, accepting your new entry. Option 2- Manual Add(if auto doesn't work): 1. right click inside the table (eg cell D14). 2. Select Insert-- Table Rpw above. Always add rows within the table to ensure your data is captured and tracked properly.
C16: 45782 | D16: Income | E16: Side Hustle( Net) | F16: 200 | H16: {=SUMPRODUCT(Tracking[Amount], --(Tracking[Date]<=Tracking[[#This Row],[Date]]), (Tracking[Type]<>"Income")*(-1) +(Tracking[Type]="Income"))} -> 2600 | I16: =IF(AND(Tracking[[#This Row],[Type]]="Income", shift_late_income_status="Active", DAY(Tracking[[#This Row],[Date]])>=shift_late_income_starting_day), DATE(YEAR(Tracking[[#This Row],[Date]]),MONTH(Tracking[[#This Row],[Date]])+1,1), Tracking[[#This Row],[Date]]) -> 45782
C17: 45782 | D17: Income | E17: Dividends | F17: 400 | H17: {=SUMPRODUCT(Tracking[Amount], --(Tracking[Date]<=Tracking[[#This Row],[Date]]), (Tracking[Type]<>"Income")*(-1) +(Tracking[Type]="Income"))} -> 2600 | I17: =IF(AND(Tracking[[#This Row],[Type]]="Income", shift_late_income_status="Active", DAY(Tracking[[#This Row],[Date]])>=shift_late_income_starting_day), DATE(YEAR(Tracking[[#This Row],[Date]]),MONTH(Tracking[[#This Row],[Date]])+1,1), Tracking[[#This Row],[Date]]) -> 45782
C18: 45784 | D18: Expenses | E18: Edu & Work tools | F18: 150 | H18: {=SUMPRODUCT(Tracking[Amount], --(Tracking[Date]<=Tracking[[#This Row],[Date]]), (Tracking[Type]<>"Income")*(-1) +(Tracking[Type]="Income"))} -> 2450 | I18: =IF(AND(Tracking[[#This Row],[Type]]="Income", shift_late_income_status="Active", DAY(Tracking[[#This Row],[Date]])>=shift_late_income_starting_day), DATE(YEAR(Tracking[[#This Row],[Date]]),MONTH(Tracking[[#This Row],[Date]])+1,1), Tracking[[#This Row],[Date]]) -> 45784
C19: 45785 | D19: Expenses | E19: Fun & Vacation | F19: 200 | H19: {=SUMPRODUCT(Tracking[Amount], --(Tracking[Date]<=Tracking[[#This Row],[Date]]), (Tracking[Type]<>"Income")*(-1) +(Tracking[Type]="Income"))} -> 2250 | I19: =IF(AND(Tracking[[#This Row],[Type]]="Income", shift_late_income_status="Active", DAY(Tracking[[#This Row],[Date]])>=shift_late_income_starting_day), DATE(YEAR(Tracking[[#This Row],[Date]]),MONTH(Tracking[[#This Row],[Date]])+1,1), Tracking[[#This Row],[Date]]) -> 45785
C20: 45787 | D20: Expenses | E20: Utilities (house media fees) | F20: 100 | H20: {=SUMPRODUCT(Tracking[Amount], --(Tracking[Date]<=Tracking[[#This Row],[Date]]), (Tracking[Type]<>"Income")*(-1) +(Tracking[Type]="Income"))} -> 2150 | I20: =IF(AND(Tracking[[#This Row],[Type]]="Income", shift_late_income_status="Active", DAY(Tracking[[#This Row],[Date]])>=shift_late_income_starting_day), DATE(YEAR(Tracking[[#This Row],[Date]]),MONTH(Tracking[[#This Row],[Date]])+1,1), Tracking[[#This Row],[Date]]) -> 45787
C21: 45789 | D21: Expenses | E21: Transportation | F21: 200 | H21: {=SUMPRODUCT(Tracking[Amount], --(Tracking[Date]<=Tracking[[#This Row],[Date]]), (Tracking[Type]<>"Income")*(-1) +(Tracking[Type]="Income"))} -> 1950 | I21: =IF(AND(Tracking[[#This Row],[Type]]="Income", shift_late_income_status="Active", DAY(Tracking[[#This Row],[Date]])>=shift_late_income_starting_day), DATE(YEAR(Tracking[[#This Row],[Date]]),MONTH(Tracking[[#This Row],[Date]])+1,1), Tracking[[#This Row],[Date]]) -> 45789
C22: 45790 | D22: Expenses | E22: Family Tax | F22: 500 | H22: {=SUMPRODUCT(Tracking[Amount], --(Tracking[Date]<=Tracking[[#This Row],[Date]]), (Tracking[Type]<>"Income")*(-1) +(Tracking[Type]="Income"))} -> 1450 | I22: =IF(AND(Tracking[[#This Row],[Type]]="Income", shift_late_income_status="Active", DAY(Tracking[[#This Row],[Date]])>=shift_late_income_starting_day), DATE(YEAR(Tracking[[#This Row],[Date]]),MONTH(Tracking[[#This Row],[Date]])+1,1), Tracking[[#This Row],[Date]]) -> 45790
C23: 45792 | D23: Expenses | E23: Health & Wellnes | F23: 600 | H23: {=SUMPRODUCT(Tracking[Amount], --(Tracking[Date]<=Tracking[[#This Row],[Date]]), (Tracking[Type]<>"Income")*(-1) +(Tracking[Type]="Income"))} -> 850 | I23: =IF(AND(Tracking[[#This Row],[Type]]="Income", shift_late_income_status="Active", DAY(Tracking[[#This Row],[Date]])>=shift_late_income_starting_day), DATE(YEAR(Tracking[[#This Row],[Date]]),MONTH(Tracking[[#This Row],[Date]])+1,1), Tracking[[#This Row],[Date]]) -> 45792
C24: 45793 | D24: Expenses | E24: Enter Expense Catergory | F24: 800 | H24: {=SUMPRODUCT(Tracking[Amount], --(Tracking[Date]<=Tracking[[#This Row],[Date]]), (Tracking[Type]<>"Income")*(-1) +(Tracking[Type]="Income"))} -> 50 | I24: =IF(AND(Tracking[[#This Row],[Type]]="Income", shift_late_income_status="Active", DAY(Tracking[[#This Row],[Date]])>=shift_late_income_starting_day), DATE(YEAR(Tracking[[#This Row],[Date]]),MONTH(Tracking[[#This Row],[Date]])+1,1), Tracking[[#This Row],[Date]]) -> 45793

Sheet Budget Dashboard
C1: Budget Dashboard | Y1: Budget Dashboard
I5: SUM(Tracking[Amount] * (Tracking[Type]= type) *(YEAR(Tracking[Effective Date])=selected_year | AQ5: Year
AN6: Select the year to view → | AQ6: 2025
AQ8: Period
AN9: Select the period to view → | AQ9: 36647
Y11: ="Breakdown - "& IF(selected_period="Total Year", selected_year & " (Total Year)", selected_period_display & " " & selected_year) -> Breakdown - May 2025 | AF11: ="Summary - "& IF(selected_period="Total Year", selected_year & " (Total Year)", selected_period_display & " " & selected_year) -> Summary - May 2025
C12: row_id | D12: header_row_id | E12: is_header | F12: is_cat | G12: is_total | H12: is_empty | I12: type | J12: item | K12: tracked | L12: budget | M12: sort_min_row | N12: sort_max_row | O12: tracked_range | P12: tracked_rank | Q12: budget_range | R12: budget_rank | S12: comb_rank | T12: comb_rank_range | U12: comb_rank_norm | V12: comb_rank_norm_run_range | W12: comb_rank_unique | X12: sortrf_row_id(lookup)
C13: {=income_header_row} -> 9 | D13: =IF(is_header, row_id, IF(NOT(is_empty), D12,-1)) -> 9 | E13: {=1*OR(row_id=income_header_row, row_id=expenses_header_row, row_id=savings_header_row)} -> 1 | F13: =1*NOT(OR(is_header, is_total, is_empty)) -> 0 | G13: {=1*OR(row_id=income_total_row, row_id=expenses_total_row, row_id=savings_total_row)} -> 0 | H13: =1*OR(row_id="/1",row_id="/2", row_id=-1) -> 0 | I13: {=IFERROR(INDEX('Budget Planning'!$C:$C, header_row_id),"")} -> Income | J13: {=IFERROR(INDEX('Budget Planning'!$C:$C, row_id),"")} -> Income | K13: ` | L13: {=IF(OR(is_header,is_empty),"", INDEX('Budget Planning'!$E:$EM, row_id, MATCH(IF(selected_period="Total Year", selected_year, DATE(selected_year, selected_period, 1)), 'Budget Planning'!$E$9:$EM$9, 0)))} | M13: {=IF(is_cat, IF(header_row_id=income_header_row,MATCH(income_min_row, $C:$C,0), IF(header_row_id=expenses_header_row,MATCH(expenses_min_row, $C:$C,0), IF(header_row_id=savings_header_row,MATCH(savings_min_row, $C:$C,0), ""))),"")} | N13: {=IF(is_cat, IF(header_row_id=income_header_row,MATCH(income_max_row, $C:$C,0), IF(header_row_id=expenses_header_row,MATCH(expenses_max_row, $C:$C,0), IF(header_row_id=savings_header_row,MATCH(savings_max_row, $C:$C,0), ""))),"")} | O13: =IF(is_cat, ADDRESS(sort_min_row, COLUMN(tracked))& ":" & ADDRESS(sort_max_row, COLUMN(tracked)),"") | P13: =IF(is_cat, RANK(tracked, INDIRECT(tracked_range), 0), "") | Q13: =IF(is_cat, ADDRESS(sort_min_row, COLUMN(budget))& ":" & ADDRESS(sort_max_row, COLUMN(budget)),"") | R13: =IF(is_cat, RANK(budget, INDIRECT(budget_range), 0), "") | S13: =IF(is_cat, _xlfn.NUMBERVALUE(tracked_rank & budget_rank), "") | T13: =IF(is_cat, ADDRESS(sort_min_row, COLUMN(com_rank))& ":" & ADDRESS(sort_max_row, COLUMN(com_rank)),"") | U13: =IF(is_cat, RANK(com_rank, INDIRECT(comb_rank_range),1), "") | V13: =IF(is_cat, ADDRESS(sort_min_row, COLUMN(comb_rank_norm))& ":" & ADDRESS(ROW(), COLUMN(comb_rank_norm)),"") | W13: =IF(is_cat, comb_rank_norm + COUNTIF(INDIRECT(comb_rank_norm_run_range), comb_rank_norm)-1, "") | X13: =IF(is_cat, header_row_id + comb_rank_unique, row_id) -> 9 | Y13: =IF(is_empty, "", INDEX($J:$J, MATCH(row_id, $X:$X,0))) -> Income | Z13: =IF(is_empty, "", IF(is_header,"Tracked", INDEX($K:$K, MATCH(row_id, $X:$X, 0)))) -> Tracked | AA13: =IF(is_empty, "", IF(is_header, "Budget", INDEX($L:$L, MATCH(row_id, $X:$X, 0)))) -> Budget | AB13: =IF(is_empty, "", IF(is_header, "%Compl.", IFERROR(out_tracked / out_budget, "-"))) -> %Compl. | AC13: =IF(is_empty, "", IF(is_header, "Remaining", IF(out_budget - out_tracked > 0, out_budget - out_tracked, 0))) -> Remaining | AD13: =IF(is_empty, "", IF(is_header, "Excess", IF(out_budget - out_tracked < 0, out_tracked - out_budget, 0))) -> Excess
C14: {=IF(C13=-1,-1, IF(C13<income_max_row,C13+1, IF(C13=income_max_row, income_total_row, IF(C13=income_total_row, "/1", IF(C13="/1", expenses_header_row, IF(C13<expenses_max_row, C13+1, IF(C13=expenses_max_row, expenses_total_row, IF(C13=expenses_total_row, "/2", IF(C13="/2", savings_header_row, IF(C13<savings_max_row, C13+1, IF(C13=savings_max_row, savings_total_row, -1)))))))))))} -> 10 | D14: =IF(is_header, row_id, IF(NOT(is_empty), D13,-1)) -> 9 | E14: {=1*OR(row_id=income_header_row, row_id=expenses_header_row, row_id=savings_header_row)} -> 0 | F14: =1*NOT(OR(is_header, is_total, is_empty)) -> 1 | G14: {=1*OR(row_id=income_total_row, row_id=expenses_total_row, row_id=savings_total_row)} -> 0 | H14: =1*OR(row_id="/1",row_id="/2", row_id=-1) -> 0 | I14: {=IFERROR(INDEX('Budget Planning'!$C:$C, header_row_id),"")} -> Income | J14: {=IFERROR(INDEX('Budget Planning'!$C:$C, row_id),"")} -> Employment (Net) | K14: {=IF(OR(is_header,is_empty), "", IF(is_total, IF(selected_period="Total Year", SUM(Tracking[Amount] * (Tracking[Type]=type) * (YEAR(Tracking[Effective Date])=selected_year)), SUM(Tracking[Amount] * (Tracking[Type]=type) * (YEAR(Tracking[Effective Date])=selected_year) * (MONTH(Tracking[Effective Date])=selected_period))), IF(selected_period="Total Year", SUM(Tracking[Amount] * (Tracking[Type]=type) *(Tracking[Category]=item)* (YEAR(Tracking[Effective Date])=selected_year)), SUM(Tracking[Amount] * (Tracking[Type]=type) *(Tracking[Category]=item)* (YEAR(Tracking[Effective Date])=selected_year)* (MONTH(Tracking[Effective Date])=selected_period)) )))} -> 3500 | L14: {=IF(OR(is_header,is_empty),"", INDEX('Budget Planning'!$E:$EM, row_id, MATCH(IF(selected_period="Total Year", selected_year, DATE(selected_year, selected_period, 1)), 'Budget Planning'!$E$9:$EM$9, 0)))} -> 2000 | M14: {=IF(is_cat, IF(header_row_id=income_header_row,MATCH(income_min_row, $C:$C,0), IF(header_row_id=expenses_header_row,MATCH(expenses_min_row, $C:$C,0), IF(header_row_id=savings_header_row,MATCH(savings_min_row, $C:$C,0), ""))),"")} -> 14 | N14: {=IF(is_cat, IF(header_row_id=income_header_row,MATCH(income_max_row, $C:$C,0), IF(header_row_id=expenses_header_row,MATCH(expenses_max_row, $C:$C,0), IF(header_row_id=savings_header_row,MATCH(savings_max_row, $C:$C,0), ""))),"")} -> 17 | O14: =IF(is_cat, ADDRESS(sort_min_row, COLUMN(tracked))& ":" & ADDRESS(sort_max_row, COLUMN(tracked)),"") -> $K$14:$K$17 | P14: =IF(is_cat, RANK(tracked, INDIRECT(tracked_range), 0), "") -> 1 | Q14: =IF(is_cat, ADDRESS(sort_min_row, COLUMN(budget))& ":" & ADDRESS(sort_max_row, COLUMN(budget)),"") -> $L$14:$L$17 | R14: =IF(is_cat, RANK(budget, INDIRECT(budget_range), 0), "") -> 1 | S14: =IF(is_cat, _xlfn.NUMBERVALUE(tracked_rank & budget_rank), "") -> 11 | T14: =IF(is_cat, ADDRESS(sort_min_row, COLUMN(com_rank))& ":" & ADDRESS(sort_max_row, COLUMN(com_rank)),"") -> $S$14:$S$17 | U14: =IF(is_cat, RANK(com_rank, INDIRECT(comb_rank_range),1), "") -> 1 | V14: =IF(is_cat, ADDRESS(sort_min_row, COLUMN(comb_rank_norm))& ":" & ADDRESS(ROW(), COLUMN(comb_rank_norm)),"") -> $U$14:$U$14 | W14: =IF(is_cat, comb_rank_norm + COUNTIF(INDIRECT(comb_rank_norm_run_range), comb_rank_norm)-1, "") -> 1 | X14: =IF(is_cat, header_row_id + comb_rank_unique, row_id) -> 10 | Y14: =IF(is_empty, "", INDEX($J:$J, MATCH(row_id, $X:$X,0))) -> Employment (Net) | Z14: =IF(is_empty, "", IF(is_header,"Tracked", INDEX($K:$K, MATCH(row_id, $X:$X, 0)))) -> 3500 | AA14: =IF(is_empty, "", IF(is_header, "Budget", INDEX($L:$L, MATCH(row_id, $X:$X, 0)))) -> 2000 | AB14: =IF(is_empty, "", IF(is_header, "%Compl.", IFERROR(out_tracked / out_budget, "-"))) -> 1.75 | AC14: =IF(is_empty, "", IF(is_header, "Remaining", IF(out_budget - out_tracked > 0, out_budget - out_tracked, 0))) -> 0 | AD14: =IF(is_empty, "", IF(is_header, "Excess", IF(out_budget - out_tracked < 0, out_tracked - out_budget, 0))) -> 1500
